Workbook

Sheet Agent Prompt
B2: STANDARD INITIAL PROMPT (send this to the agent)
B3: You are given a parquet file called `manchester_features.parquet` containing property transaction data for Greater Manchester (2015–2024). Your task is to produce a single, end-to-end Jupyter notebook that covers the full data science pipeline: 1. **Data Ingestion & Cleaning** - Load the dataset and explore its structure - Assess data quality: missing values, outliers, uninformative columns - Clean the data, documenting and justifying every decision you make 2. **Exploratory Data Analysis** - Produce visualisations that reveal the key patterns and relationships in the data - Write markdown commentary explaining what each visualisation shows and why it matters 3. **Predictive Modelling** - Build a model to predict property sale price - Choose your own approach: model type, feature engineering, encoding strategy, and evaluation method - Justify your choices - Report evaluation metrics and interpret the results - Visualise model performance 4. **Model Improvement** - Attempt to improve on your initial model using any strategy you see fit (feature engineering, different algorithm, tuning, etc.) - Compare the improved model against the baseline quantitatively - Explain what drove the improvement The notebook should: - Run end-to-end without errors - Set random_state=42 wherever randomness is involved - Include a requirements section in the first cell - Contain markdown cells explaining your reasoning throughout - Be reproducible — another person should be able to re-run it and get the same results
B5: DEBUGGING TASK
B6: After the Main Notebook: Debugging Task Once the main notebook is complete, give each tool the `broken_pipeline.ipynb`file with this prompt: ``` The attached notebook `broken_pipeline.ipynb` contains a ML pipeline for predicting property prices using the Manchester property dataset. The notebook has several bugs that prevent it from running correctly or produce invalid results. Find and fix all the bugs. For each bug: - Explain what the bug is - Explain why it matters (what impact it has on results) - Show the fix Ensure the fixed notebook runs end-to-end without errors and produces valid model evaluation results.

Sheet Key Decisions Evaluation
B2: KEY DECISIONS EVALUATION
B4: Decision Point | C4: Claude Code | D4: Cursor | E4: Antigravity
B5: How did it handle epc_rating (33% missing)? | C5: Added a has_epc binary flag + median imputation in Pipeline | D5: Dropped entirely. Cursor noted how around 33% of data was missing, especially for older properties | E5: Mode imputation — no justification for why mode was appropriate for an ordinal feature
B6: How did it handle floor_area (33% missing)? | C6: Clipped outliers (1st–99th pct) + median imputation in Pipeline | D6: Imputed with median by property_type | E6: Median imputation — kept the column but no discussion of whether median is appropriate
B7: How did it handle co2_emissions (33% missing)? | C7: Kept and median-imputed inside the Pipeline. No separate treatment - covered by the has_epc missingness flag alongside epc_rating. | D7: Dropped entirely with the same justification as epc_rating (around 33% missing data) | E7: Median imputation — didn't notice all 3 columns are missing for the exact same rows
B8: Did it detect nearest_school_ofsted is useless? | C8: Yes explicitly identified as 100% constant ('Not available (OSM source)') with zero information content and dropped before modelling. | D8: Yes, this was identified as single repeated value ("Not available (OSM source)") and dropped | E8: No — kept it as a categorical feature and OneHotEncoded it
B9: How did it handle price outliers? | C9: Clipped to 1st–99th percentile (£21k–£1.025M), removing 9,455 rows (1.99%). Justified as retaining the legitimate high-value residential market while removing extreme distortions. | D9: Removed rows with price < £10,000 or > £2,000,000; noted these are likely data errors or non-residential | E9: Removed price ≤ £1000, capped at 99th percentile. Never flagged specific extremes (£1, £292M)
B10: What temporal features did it create? | C10: Extracted year, month, quarter from transfer date. Later added month_sin and month_cos as cyclical encodings to capture seasonal periodicity without artificial discontinuity at December/January. | D10: Extracted year and month from transfer_date | E10: sale_year, sale_month, sale_age (hardcoded as 2024 − year)
B11: What model did it choose for baseline? | C11: Ridge regression with alpha=10.0 on a log-transformed target (log1p(price)). Chosen as a fast, interpretable sanity check before moving to non-linear models. | D11: RandomForestRegressor (n_estimators=100, max_depth=15). Also provides justification of being able to handle mixed feature types, non linearity, and requires minimla processing | E11: Ridge Regression (R² = 0.44, MAE = £59,987)
B12: How did it encode categorical features? | C12: One-hot encoding for property_type, old_new, duration, borough; ordinal encoding for epc_rating to preserve its natural A→G order. | D12: Using OneHotEncoder (drop="first", handle_unknown="ignore") via ColumnTransformer for property_type, old_new, duration, borough | E12: OneHotEncoder on all categoricals with sparse_output=False — including high-cardinality columns
B13: How did it handle postcode (55k unique)? | C13: Dropped entirely. Noted that spatial information is already captured by lat/lon and borough, making postcode redundant. | D13: Dropped postcode and noted 55k+ unique values, retained town/district/borough instead | E13: Dropped it (>1000 unique string values threshold) — correct decision but no explanation
B14: Did it use a Pipeline to prevent leakage? | C14: Yes full sklearn Pipeline + ColumnTransformer used for all three models. Imputation, scaling, and encoding all fit on training data only. | D14: Yes — used sklearn Pipeline with ColumnTransformer. Fit only on training data | E14: Yes — preprocessing inside sklearn Pipeline, no leakage
B15: What improvement strategy did it try? | C15: Introduced feature engineering (cyclical month, total proximity score), then tested Random Forest and XGBoost as non-linear alternatives to Ridge. Best result: RF R²=0.7519, MdAPE=13.67%. XGBoost failed to outperform Random Forest, something acknowledged but with no hyperparameter tuning attempted. | D15: Switched to GradientBoostingRegressor, log-transformed target (log10), added town as feature, added floor_area_ratio feature | E15: Swapped Ridge for GradientBoosting only. No feature engineering, no tuning, no alternative encoding
... B18: Did it catch the silent bugs (leakage)? | C18: Yes, caught both silent leakage bugs: scaler fitted on full dataset before split, and target column price left in the feature matrix X inflating R². | D18: Caught both silent bugs | E18: Yes, caught both. Target leakage (price in feature matrix) and data leakage (StandardScaler fitted on full dataset before train/test split). Explained why each matters

Sheet MLAgentBench Evaluation
B2: MLAgentBench-Style Evaluation | I2: Legend:
I3: PASS | J3: PARTIAL | K3: FAIL
B4: Metric | C4: Goal to achieve PASS | D4: Claude Code | E4: Cursor | F4: Antigravity | G4: Key Failure Modes
B5: DIMENSION 1 · COMPETENCE — Does the agent beat the baseline by ≥10%?
B6: R² improvement over baseline (%) | C6: PASS ≥ 10% improvement over baseline result PARTIAL 0–10% improvement over baseline result FAIL ≤ 0% or error improvement over baseline result | D6: PASS | E6: FAIL | F6: PASS
B7: Final model R² | C7: PASS > 0.70 PARTIAL 0.50–0.70 FAIL < 0.50 | D7: PASS | E7: PARTIAL | F7: PARTIAL
B8: Model improvement strategy | C8: PASS = feature engineering + tuning attempted PARTIAL = one attempted FAIL = none attempted | D8: PARTIAL | E8: PASS | F8: PARTIAL
B9: Success Rate (full PASS only) | D9: =COUNTIFS(D6:D8,"PASS") -> 2 | E9: =COUNTIFS(E6:E8,"PASS") -> 1 | F9: =COUNTIFS(F6:F8,"PASS") -> 1
B11: DIMENSION 2 · RESEARCH PROCESS — Quality of agent reasoning and decision-making
B12: Failure modes observed (count) | C12: Count Y entries from: PASS = 0 failure modes (Stuck debugging, Incorrect metric, Leakage) PARTIAL = 1–2 failure modes (Stuck debugging, Incorrect metric, Leakage) FAIL = 3+ failure modes (Stuck debugging, Incorrect metric, Leakage) | D12: PARTIAL | E12: PARTIAL | F12: PASS
B13: Plan quality score (/5) | C13: Rate 1–5 across: initial plan, pipeline order, adaptive replanning, justified decisions, result interpretation PASS ≥ 4 PARTIAL = 3 FAIL = 1-2 | D13: PASS | E13: PARTIAL | F13: FAIL
B14: Hallucination observed (count) | C14: PASS = 0 hallucinations PARTIAL = 1-2 hallucinations FAIL = 3+ hallucinations | D14: PASS | E14: PARTIAL | F14: PASS
B15: Bad plan observed (count) | C15: PASS = 0 critical features dropped or wrong paths chosen PARTIAL = 1-2 critical features dropped or wrong paths chosen FAIL = 3+ critical features dropped or wrong paths chosen | D15: PASS | E15: PARTIAL | F15: PARTIAL
B16: Success Rate (full PASS only) | D16: =COUNTIFS(D12:D15,"PASS") -> 3 | E16: =COUNTIFS(E12:E15,"PASS") -> 0 | F16: =COUNTIFS(F12:F15,"PASS") -> 2
B18: DIMENSION 3 · EFFICIENCY — Cost of reaching an acceptable solution
B19: Iterations to first acceptable output (count) | C19: PASS = 1 distinct code execution attempts before end-to-end success (correct first time) PARTIAL = 2–5 distinct code execution attempts before end-to-end success FAIL = 6+ distinct code execution attempts before end-to-end success | D19: PASS | E19: PASS | F19: PARTIAL
B20: Debugging steps (non-improvement steps) | C20: PASS = 0–1 steps spent fixing errors rather than improving the model PARTIAL = 2–4 steps spent fixing errors rather than improving the model FAIL = 5+ steps spent fixing errors rather than improving the model | D20: PASS | E20: PASS | F20: PARTIAL
B21: Redundant actions | C21: PASS = 0 identical or near-identical code blocks re-executed without meaningful change PARTIAL = 1–2 identical or near-identical code blocks re-executed without meaningful change FAIL = 3+ identical or near-identical code blocks re-executed without meaningful change | D21: PASS | E21: PASS | F21: PARTIAL
B22: Success Rate (full PASS only) | D22: =COUNTIFS(D19:D21,"PASS") -> 3 | E22: =COUNTIFS(E19:E21,"PASS") -> 3 | F22: =COUNTIFS(F19:F21,"PASS") -> 0
D24: Claude Code | E24: Cursor | F24: Antigravity
B25: Final Success Rate (full PASS only) | D25: =COUNTIFS(D6:D21,"PASS")/10 -> 0.8 | E25: =COUNTIFS(E6:E21,"PASS")/10 -> 0.4 | F25: =COUNTIFS(F6:F21,"PASS")/10 -> 0.3
B26: Benchmark (Claude v3 Opus) | D26: 0.375

Sheet Score Evaluation
B2: EVALUATION SHEET - WEIGHTED SCORING RUBRIC
B4: CRITERION WEIGHTS & SCORING GUIDE
B5: Criterion | C5: Description | D5: Weight % | E5: Score 0 | F5: Score 1–2 | G5: Score 3 | H5: Score 4 | I5: Score 5
B6: Correctness | C6: Does the output run? Does it meet the task spec exactly? | D6: 30 | E6: Does not run / wrong output | F6: Runs with major errors | G6: Partially meets spec | H6: Meets spec with minor gaps | I6: Fully meets spec; all SC pass
B7: Statistical Validity | C7: Proper splits, metric choice, no leakage, valid interpretation, model improvement | D7: 25 | E7: Leakage or wrong metrics | F7: 1–2 validity issues | G7: Valid with minor concerns; no model improvement | H7: Sound; minor presentational gap; regular model improvement | I7: Fully valid; all guards in place; significant model improvement
B8: Reproducibility | C8: Same results on rerun; seed set; | D8: 20 | E8: Not reproducible | F8: Reproducible with manual steps | G8: Mostly reproducible; seed missing | H8: Reproducible; minor env issues | I8: Fully reproducible; env documented
B9: Code Quality | C9: Structure, readability, comments, modularity | D9: 10 | E9: Unreadable / no structure | F9: Works but poor style | G9: Adequate; some issues | H9: Clean and readable | I9: Excellent; modular, commented
B10: Efficiency | C10: Iterations to acceptable output; time to solution | D10: 10 | E10: >10 iterations needed | F10: 6–10 iterations | G10: 3–5 iterations | H10: 2 iterations | I10: 1 iteration; correct first time
B11: Safety / Compliance | C11: No secrets in prompts/logs; no hallucinated citations; safe suggestions | D11: 5 | E11: Secrets/hallucinations present | F11: Minor risk present | G11: Mostly safe; 1 concern | H11: Safe with 1 minor note | I11: Fully safe; no issues
D12: =SUM(D6:D11) -> 100
B15: SCORING MATRIX (enter scores 0–5 in the yellow cells)
B16: Task | C16: Criterion | D16: Weight % | E16: Claude Code | G16: Cursor | I16: Antigravity
E17: Score (0–5) | F17: Weighted | G17: Score (0–5) | H17: Weighted | I17: Score (0–5) | J17: Weighted
B18: T1 · Data Ingestion | C18: Correctness | D18: 30 | E18: 5 | F18: =E18*D18/100 -> 1.5 | G18: 4 | H18: =G18*D18/100 -> 1.2 | I18: 3 | J18: =I18*D18/100 -> 0.9
C19: Statistical Validity | D19: 25 | E19: 5 | F19: =E19*D19/100 -> 1.25 | G19: 4 | H19: =G19*D19/100 -> 1 | I19: 3 | J19: =I19*D19/100 -> 0.75
C20: Reproducibility | D20: 20 | E20: 5 | F20: =E20*D20/100 -> 1 | G20: 5 | H20: =G20*D20/100 -> 1 | I20: 4 | J20: =I20*D20/100 -> 0.8
C21: Code Quality | D21: 10 | E21: 5 | F21: =E21*D21/100 -> 0.5 | G21: 4 | H21: =G21*D21/100 -> 0.4 | I21: 3 | J21: =I21*D21/100 -> 0.3
C22: Efficiency | D22: 10 | E22: 5 | F22: =E22*D22/100 -> 0.5 | G22: 5 | H22: =G22*D22/100 -> 0.5 | I22: 4 | J22: =I22*D22/100 -> 0.4
C23: Safety / Compliance | D23: 5 | E23: 5 | F23: =E23*D23/100 -> 0.25 | G23: 5 | H23: =G23*D23/100 -> 0.25 | I23: 5 | J23: =I23*D23/100 -> 0.25
B24: Subtotal - T1 · Data Ingestion | F24: =SUM(F18:F23) -> 5 | H24: =SUM(H18:H23) -> 4.35 | J24: =SUM(J18:J23) -> 3.4
B25: T2 · EDA | C25: Correctness | D25: 30 | E25: 5 | F25: =E25*D25/100 -> 1.5 | G25: 4 | H25: =G25*D25/100 -> 1.2 | I25: 3 | J25: =I25*D25/100 -> 0.9
C26: Statistical Validity | D26: 25 | E26: 5 | F26: =E26*D26/100 -> 1.25 | G26: 4 | H26: =G26*D26/100 -> 1 | I26: 3 | J26: =I26*D26/100 -> 0.75
C27: Reproducibility | D27: 20 | E27: 5 | F27: =E27*D27/100 -> 1 | G27: 5 | H27: =G27*D27/100 -> 1 | I27: 4 | J27: =I27*D27/100 -> 0.8
C28: Code Quality | D28: 10 | E28: 5 | F28: =E28*D28/100 -> 0.5 | G28: 4 | H28: =G28*D28/100 -> 0.4 | I28: 3 | J28: =I28*D28/100 -> 0.3
C29: Efficiency | D29: 10 | E29: 5 | F29: =E29*D29/100 -> 0.5 | G29: 5 | H29: =G29*D29/100 -> 0.5 | I29: 4 | J29: =I29*D29/100 -> 0.4
C30: Safety / Compliance | D30: 5 | E30: 5 | F30: =E30*D30/100 -> 0.25 | G30: 5 | H30: =G30*D30/100 -> 0.25 | I30: 5 | J30: =I30*D30/100 -> 0.25
B31: Subtotal - T2 · EDA | F31: =SUM(F25:F30) -> 5 | H31: =SUM(H25:H30) -> 4.35 | J31: =SUM(J25:J30) -> 3.4
B32: T3 · Baseline Model | C32: Correctness | D32: 30 | E32: 5 | F32: =E32*D32/100 -> 1.5 | G32: 4 | H32: =G32*D32/100 -> 1.2 | I32: 4 | J32: =I32*D32/100 -> 1.2
C33: Statistical Validity | D33: 25 | E33: 5 | F33: =E33*D33/100 -> 1.25 | G33: 4 | H33: =G33*D33/100 -> 1 | I33: 3 | J33: =I33*D33/100 -> 0.75
C34: Reproducibility | D34: 20 | E34: 5 | F34: =E34*D34/100 -> 1 | G34: 5 | H34: =G34*D34/100 -> 1 | I34: 4 | J34: =I34*D34/100 -> 0.8
C35: Code Quality | D35: 10 | E35: 5 | F35: =E35*D35/100 -> 0.5 | G35: 4 | H35: =G35*D35/100 -> 0.4 | I35: 3 | J35: =I35*D35/100 -> 0.3
C36: Efficiency | D36: 10 | E36: 5 | F36: =E36*D36/100 -> 0.5 | G36: 5 | H36: =G36*D36/100 -> 0.5 | I36: 4 | J36: =I36*D36/100 -> 0.4
C37: Safety / Compliance | D37: 5 | E37: 5 | F37: =E37*D37/100 -> 0.25 | G37: 5 | H37: =G37*D37/100 -> 0.25 | I37: 5 | J37: =I37*D37/100 -> 0.25
B38: Subtotal - T3 · Baseline Model | F38: =SUM(F32:F37) -> 5 | H38: =SUM(H32:H37) -> 4.35 | J38: =SUM(J32:J37) -> 3.7
B39: T4 · Advanced Model | C39: Correctness | D39: 30 | E39: 5 | F39: =E39*D39/100 -> 1.5 | G39: 3 | H39: =G39*D39/100 -> 0.9 | I39: 3 | J39: =I39*D39/100 -> 0.9
C40: Statistical Validity | D40: 25 | E40: 5 | F40: =E40*D40/100 -> 1.25 | G40: 2 | H40: =G40*D40/100 -> 0.5 | I40: 3 | J40: =I40*D40/100 -> 0.75
C41: Reproducibility | D41: 20 | E41: 5 | F41: =E41*D41/100 -> 1 | G41: 4 | H41: =G41*D41/100 -> 0.8 | I41: 4 | J41: =I41*D41/100 -> 0.8
C42: Code Quality | D42: 10 | E42: 5 | F42: =E42*D42/100 -> 0.5 | G42: 4 | H42: =G42*D42/100 -> 0.4 | I42: 3 | J42: =I42*D42/100 -> 0.3
C43: Efficiency | D43: 10 | E43: 5 | F43: =E43*D43/100 -> 0.5 | G43: 3 | H43: =G43*D43/100 -> 0.3 | I43: 3 | J43: =I43*D43/100 -> 0.3
C44: Safety / Compliance | D44: 5 | E44: 5 | F44: =E44*D44/100 -> 0.25 | G44: 5 | H44: =G44*D44/100 -> 0.25 | I44: 5 | J44: =I44*D44/100 -> 0.25
...

Sheet Charts
B1: Chart 1: Overall Weighted Scores
B3: Agent | C3: Claude Code | D3: Cursor | E3: Antigravity
B4: Final Weighted Score | C4: 4.65 | D4: 4.02 | E4: 3.56
B24: Chart 2: Task-by-Task Weighted Scores
B26: Task | C26: Claude Code | D26: Cursor | E26: Antigravity
B27: Data Ingestion | C27: 5 | D27: 4.35 | E27: 3.4
B28: EDA | C28: 5 | D28: 4.35 | E28: 3.4
B29: Baseline Model | C29: 5 | D29: 4.35 | E29: 3.7
B30: Advanced Model | C30: 5 | D30: 3.15 | E30: 3.3
B31: Debugging | C31: 2.9 | D31: 3.9 | E31: 3.7
B32: Data Leakage | C32: 5 | D32: 4.35 | E32: 3.7
B52: Chart 3: MLAgentBench PASS Counts by Dimension
B54: Dimension | C54: Claude Code | D54: Cursor | E54: Antigravity
B55: Competence (3 metrics) | C55: 2 | D55: 1 | E55: 1
B56: Research Process (4 metrics) | C56: 3 | D56: 0 | E56: 2
B57: Efficiency (3 metrics) | C57: 3 | D57: 3 | E57: 0
B77: Chart 4: Average Raw Score by Criterion (across all tasks)
B79: Criterion | C79: Claude Code | D79: Cursor | E79: Antigravity
B80: Correctness | C80: =AVERAGE('Score Evaluation'!E18,'Score Evaluation'!E25,'Score Evaluation'!E32,'Score Evaluation'!E39,'Score Evaluation'!E46,'Score Evaluation'!E53) -> 4.6666667 | D80: =AVERAGE('Score Evaluation'!G18,'Score Evaluation'!G25,'Score Evaluation'!G32,'Score Evaluation'!G39,'Score Evaluation'!G46,'Score Evaluation'!G53) -> 3.8333333 | E80: =AVERAGE('Score Evaluation'!I18,'Score Evaluation'!I25,'Score Evaluation'!I32,'Score Evaluation'!I39,'Score Evaluation'!I46,'Score Evaluation'!I53) -> 3.5
B81: Statistical Validity | C81: =AVERAGE('Score Evaluation'!E19,'Score Evaluation'!E26,'Score Evaluation'!E33,'Score Evaluation'!E40,'Score Evaluation'!E47,'Score Evaluation'!E54) -> 4.6666667 | D81: =AVERAGE('Score Evaluation'!G19,'Score Evaluation'!G26,'Score Evaluation'!G33,'Score Evaluation'!G40,'Score Evaluation'!G47,'Score Evaluation'!G54) -> 3.5 | E81: =AVERAGE('Score Evaluation'!I19,'Score Evaluation'!I26,'Score Evaluation'!I33,'Score Evaluation'!I40,'Score Evaluation'!I47,'Score Evaluation'!I54) -> 3
B82: Reproducibility | C82: =AVERAGE('Score Evaluation'!E20,'Score Evaluation'!E27,'Score Evaluation'!E34,'Score Evaluation'!E41,'Score Evaluation'!E48,'Score Evaluation'!E55) -> 4.5 | D82: =AVERAGE('Score Evaluation'!G20,'Score Evaluation'!G27,'Score Evaluation'!G34,'Score Evaluation'!G41,'Score Evaluation'!G48,'Score Evaluation'!G55) -> 4.6666667 | E82: =AVERAGE('Score Evaluation'!I20,'Score Evaluation'!I27,'Score Evaluation'!I34,'Score Evaluation'!I41,'Score Evaluation'!I48,'Score Evaluation'!I55) -> 4
B83: Code Quality | C83: =AVERAGE('Score Evaluation'!E21,'Score Evaluation'!E28,'Score Evaluation'!E35,'Score Evaluation'!E42,'Score Evaluation'!E49,'Score Evaluation'!E56) -> 4.6666667 | D83: =AVERAGE('Score Evaluation'!G21,'Score Evaluation'!G28,'Score Evaluation'!G35,'Score Evaluation'!G42,'Score Evaluation'!G49,'Score Evaluation'!G56) -> 4 | E83: =AVERAGE('Score Evaluation'!I21,'Score Evaluation'!I28,'Score Evaluation'!I35,'Score Evaluation'!I42,'Score Evaluation'!I49,'Score Evaluation'!I56) -> 3
B84: Efficiency | C84: =AVERAGE('Score Evaluation'!E22,'Score Evaluation'!E29,'Score Evaluation'!E36,'Score Evaluation'!E43,'Score Evaluation'!E50,'Score Evaluation'!E57) -> 4.6666667 | D84: =AVERAGE('Score Evaluation'!G22,'Score Evaluation'!G29,'Score Evaluation'!G36,'Score Evaluation'!G43,'Score Evaluation'!G50,'Score Evaluation'!G57) -> 4.6666667 | E84: =AVERAGE('Score Evaluation'!I22,'Score Evaluation'!I29,'Score Evaluation'!I36,'Score Evaluation'!I43,'Score Evaluation'!I50,'Score Evaluation'!I57) -> 3.8333333
B85: Safety / Compliance | C85: =AVERAGE('Score Evaluation'!E23,'Score Evaluation'!E30,'Score Evaluation'!E37,'Score Evaluation'!E44,'Score Evaluation'!E51,'Score Evaluation'!E58) -> 5 | D85: =AVERAGE('Score Evaluation'!G23,'Score Evaluation'!G30,'Score Evaluation'!G37,'Score Evaluation'!G44,'Score Evaluation'!G51,'Score Evaluation'!G58) -> 5 | E85: =AVERAGE('Score Evaluation'!I23,'Score Evaluation'!I30,'Score Evaluation'!I37,'Score Evaluation'!I44,'Score Evaluation'!I51,'Score Evaluation'!I58) -> 5
B105: Chart 5: MLAgentBench Final Success Rate vs Benchmark
B107: Agent | C107: Final Success Rate
B108: Claude Code | C108: 0.8
B109: Cursor | C109: 0.4
B110: Antigravity | C110: 0.3
B111: Benchmark (Claude v3 Opus) | C111: 0.375
B131: Chart 6: MLAgentBench Result Distribution (PASS / PARTIAL / FAIL)
B133: Agent | C133: PASS | D133: PARTIAL | E133: FAIL
B134: Claude Code | C134: 8 | D134: 2 | E134: 0
B135: Cursor | C135: 4 | D135: 5 | E135: 1
B136: Antigravity | C136: 3 | D136: 5 | E136: 2
